Workbook

Sheet Historical Financials
B1: MARUTI SUZUKI LTD
B2: (IN CRORES)
B3: ="Historical Financial Statement"&" - "&B1 -> Historical Financial Statement - MARUTI SUZUKI LTD
B4: Year | C4: 2016 | D4: =C4+1 -> 2017 | E4: =D4+1 -> 2018 | F4: =E4+1 -> 2019 | G4: =F4+1 -> 2020 | H4: =G4+1 -> 2021 | I4: =H4+1 -> 2022 | J4: =I4+1 -> 2023 | K4: =J4+1 -> 2024 | L4: =K4+1 -> 2025
B6: ="Income Statement"&" - "&B1 -> Income Statement - MARUTI SUZUKI LTD
B7: Revenue | C7: ='Data Sheet'!B17 -> 57589 | D7: ='Data Sheet'!C17 -> 68085 | E7: ='Data Sheet'!D17 -> 79809.4 | F7: ='Data Sheet'!E17 -> 86068.5 | G7: ='Data Sheet'!F17 -> 75660 | H7: ='Data Sheet'!G17 -> 70372 | I7: ='Data Sheet'!H17 -> 88329.8 | J7: ='Data Sheet'!I17 -> 118409.9 | ... L7: ='Data Sheet'!K17 -> 152913
B8: COGS | C8: =SUM('Data Sheet'!B18,'Data Sheet'!B20,'Data Sheet'!B21,'Data Sheet'!B22)*1-'Data Sheet'!B19 -> 41828.2 | D8: =SUM('Data Sheet'!C18,'Data Sheet'!C20,'Data Sheet'!C21,'Data Sheet'!C22)*1-'Data Sheet'!C19 -> 50004 | E8: =SUM('Data Sheet'!D18,'Data Sheet'!D20,'Data Sheet'!D21,'Data Sheet'!D22)*1-'Data Sheet'!D19 -> 58985 | F8: =SUM('Data Sheet'!E18,'Data Sheet'!E20,'Data Sheet'!E21,'Data Sheet'!E22)*1-'Data Sheet'!E19 -> 64182.2 | G8: =SUM('Data Sheet'!F18,'Data Sheet'!F20,'Data Sheet'!F21,'Data Sheet'!F22)*1-'Data Sheet'!F19 -> 57657.1 | H8: =SUM('Data Sheet'!G18,'Data Sheet'!G20,'Data Sheet'!G21,'Data Sheet'!G22)*1-'Data Sheet'!G19 -> 55415.6 | I8: =SUM('Data Sheet'!H18,'Data Sheet'!H20,'Data Sheet'!H21,'Data Sheet'!H22)*1-'Data Sheet'!H19 -> 71578.8 | J8: =SUM('Data Sheet'!I18,'Data Sheet'!I20,'Data Sheet'!I21,'Data Sheet'!I22)*1-'Data Sheet'!I19 -> 92730.6 | ... L8: =SUM('Data Sheet'!K18,'Data Sheet'!K20,'Data Sheet'!K21,'Data Sheet'!K22)*1-'Data Sheet'!K19 -> 114516.8
B9: Gross Profit | C9: =C7-C8 -> 15760.8 | D9: =D7-D8 -> 18081 | E9: =E7-E8 -> 20824.4 | F9: =F7-F8 -> 21886.3 | G9: =G7-G8 -> 18002.9 | H9: =H7-H8 -> 14956.4 | I9: =I7-I8 -> 16751 | J9: =J7-J8 -> 25679.3 | ... L9: =L7-L8 -> 38396.2
B10: Selling & General Expenses | C10: =SUM('Data Sheet'!B23:B24) -> 6736.7 | D10: =SUM('Data Sheet'!C23:C24) -> 7659.7 | E10: =SUM('Data Sheet'!D23:D24) -> 8706.5 | F10: =SUM('Data Sheet'!E23:E24) -> 10830 | G10: =SUM('Data Sheet'!F23:F24) -> 10647.9 | H10: =SUM('Data Sheet'!G23:G24) -> 9545.8 | I10: =SUM('Data Sheet'!H23:H24) -> 10999 | J10: =SUM('Data Sheet'!I23:I24) -> 12557.8 | ... L10: =SUM('Data Sheet'!K23:K24) -> 18239.9
B11: EBITDA | C11: =C9-C10 -> 9024.1 | D11: =D9-D10 -> 10421.3 | E11: =E9-E10 -> 12117.9 | F11: =F9-F10 -> 11056.3 | G11: =G9-G10 -> 7355 | H11: =H9-H10 -> 5410.6 | I11: =I9-I10 -> 5752 | J11: =J9-J10 -> 13121.5 | ... L11: =L9-L10 -> 20156.3
B12: Depreciation | C12: ='Data Sheet'!B26 -> 2821.8 | D12: ='Data Sheet'!C26 -> 2603.9 | E12: ='Data Sheet'!D26 -> 2759.8 | F12: ='Data Sheet'!E26 -> 3020.8 | G12: ='Data Sheet'!F26 -> 3528.4 | H12: ='Data Sheet'!G26 -> 3034.1 | I12: ='Data Sheet'!H26 -> 2789 | J12: ='Data Sheet'!I26 -> 4846 | ... L12: ='Data Sheet'!K26 -> 5608.2
B13: EBIT | C13: =C11-C12 -> 6202.3 | D13: =D11-D12 -> 7817.4 | E13: =E11-E12 -> 9358.1 | F13: =F11-F12 -> 8035.5 | G13: =G11-G12 -> 3826.6 | H13: =H11-H12 -> 2376.5 | I13: =I11-I12 -> 2963 | J13: =J11-J12 -> 8275.5 | ... L13: =L11-L12 -> 14548.1
B14: Interest | C14: ='Data Sheet'!B27 -> 81.7 | D14: ='Data Sheet'!C27 -> 89.4 | E14: ='Data Sheet'!D27 -> 345.8 | F14: ='Data Sheet'!E27 -> 75.9 | G14: ='Data Sheet'!F27 -> 134.2 | H14: ='Data Sheet'!G27 -> 101.8 | I14: ='Data Sheet'!H27 -> 126.6 | J14: ='Data Sheet'!I27 -> 252.3 | ... L14: ='Data Sheet'!K27 -> 194.2
B15: Other Income | C15: ='Data Sheet'!B25 -> 1464.1 | D15: ='Data Sheet'!C25 -> 2399.2 | E15: ='Data Sheet'!D25 -> 2154.6 | F15: ='Data Sheet'!E25 -> 2664.2 | G15: ='Data Sheet'!F25 -> 3410.4 | H15: ='Data Sheet'!G25 -> 3046.3 | I15: ='Data Sheet'!H25 -> 1860.8 | J15: ='Data Sheet'!I25 -> 2415 | ... L15: ='Data Sheet'!K25 -> 5266.1
B16: EBT | C16: =C13-SUM(C14:C15) -> 4656.5 | D16: =D13-SUM(D14:D15) -> 5328.8 | E16: =E13-SUM(E14:E15) -> 6857.7 | F16: =F13-SUM(F14:F15) -> 5295.4 | G16: =G13-SUM(G14:G15) -> 282 | H16: =H13-SUM(H14:H15) -> -771.6 | I16: =I13-SUM(I14:I15) -> 975.6 | J16: =J13-SUM(J14:J15) -> 5608.2 | ... L16: =L13-SUM(L14:L15) -> 9087.8
B17: Tax | C17: ='Data Sheet'!B29 -> 2087.5 | D17: ='Data Sheet'!C29 -> 2616.2 | E17: ='Data Sheet'!D29 -> 3286.2 | F17: ='Data Sheet'!E29 -> 2973.2 | G17: ='Data Sheet'!F29 -> 1425.2 | H17: ='Data Sheet'!G29 -> 931.9 | I17: ='Data Sheet'!H29 -> 817.7 | J17: ='Data Sheet'!I29 -> 2174.5 | ... L17: ='Data Sheet'!K29 -> 5119.8
B18: Net Income | C18: =C16-C17 -> 2569 | D18: =D16-D17 -> 2712.6 | E18: =E16-E17 -> 3571.5 | F18: =F16-F17 -> 2322.2 | G18: =G16-G17 -> -1143.2 | H18: =H16-H17 -> -1703.5 | I18: =I16-I17 -> 157.9 | J18: =J16-J17 -> 3433.7 | ... L18: =L16-L17 -> 3968
B20: No. of Equity Shares | C20: ='Data Sheet'!B57/'Data Sheet'!B72 -> 30.2 | D20: ='Data Sheet'!C57/'Data Sheet'!C72 -> 30.2 | E20: ='Data Sheet'!D57/'Data Sheet'!D72 -> 30.2 | F20: ='Data Sheet'!E57/'Data Sheet'!E72 -> 30.2 | G20: ='Data Sheet'!F57/'Data Sheet'!F72 -> 30.2 | H20: ='Data Sheet'!G57/'Data Sheet'!G72 -> 30.2 | I20: ='Data Sheet'!H57/'Data Sheet'!H72 -> 30.2 | J20: ='Data Sheet'!I57/'Data Sheet'!I72 -> 31.44 | ... L20: ='Data Sheet'!K57/'Data Sheet'!K72 -> 31.44
B22: EPS | C22: =C18/C20 -> 85.066225 | D22: =D18/D20 -> 89.821192 | E22: =E18/E20 -> 118.26159 | F22: =F18/F20 -> 76.89404 | G22: =G18/G20 -> -37.854305 | H22: =H18/H20 -> -56.407285 | I22: =I18/I20 -> 5.2284768 | J22: =J18/J20 -> 109.21438 | ... L22: =L18/L20 -> 126.20865
B24: DPS | C24: ='Data Sheet'!B31/'Historical Financials'!C20 -> 35 | D24: ='Data Sheet'!C31/'Historical Financials'!D20 -> 75 | E24: ='Data Sheet'!D31/'Historical Financials'!E20 -> 80 | F24: ='Data Sheet'!E31/'Historical Financials'!F20 -> 80 | G24: ='Data Sheet'!F31/'Historical Financials'!G20 -> 60 | H24: ='Data Sheet'!G31/'Historical Financials'!H20 -> 45 | I24: ='Data Sheet'!H31/'Historical Financials'!I20 -> 60 | J24: ='Data Sheet'!I31/'Historical Financials'!J20 -> 90 | ... L24: ='Data Sheet'!K31/'Historical Financials'!L20 -> 135
B25: Dividend Payout Ratio % | C25: =C24/C22 -> 0.41144414 | D25: =D24/D22 -> 0.83499226 | E25: =E24/E22 -> 0.67646647 | F25: =F24/F22 -> 1.0403927 | G25: =G24/G22 -> -1.5850245 | H25: =H24/H22 -> -0.7977693 | I25: =I24/I22 -> 11.475617 | J25: =J24/J22 -> 0.82406733 | ... L25: =L24/L22 -> 1.0696573
B27: Retained Earnings % | C27: =IFERROR(IF(C22>C24,1-C25,0),0) -> 0.58855586 | D27: =IFERROR(IF(D22>D24,1-D25,0),0) -> 0.16500774 | E27: =IFERROR(IF(E22>E24,1-E25,0),0) -> 0.32353353 | F27: =IFERROR(IF(F22>F24,1-F25,0),0) -> 0 | G27: =IFERROR(IF(G22>G24,1-G25,0),0) -> 0 | H27: =IFERROR(IF(H22>H24,1-H25,0),0) -> 0 | I27: =IFERROR(IF(I22>I24,1-I25,0),0) -> 0 | J27: =IFERROR(IF(J22>J24,1-J25,0),0) -> 0.17593267 | ... L27: =IFERROR(IF(L22>L24,1-L25,0),0) -> 0
B29: ="Balance Sheet"&" - "&B1 -> Balance Sheet - MARUTI SUZUKI LTD
B30: Equity Share Capital | C30: ='Data Sheet'!B57 -> 151 | D30: ='Data Sheet'!C57 -> 151 | E30: ='Data Sheet'!D57 -> 151 | F30: ='Data Sheet'!E57 -> 151 | G30: ='Data Sheet'!F57 -> 151 | H30: ='Data Sheet'!G57 -> 151 | I30: ='Data Sheet'!H57 -> 151 | J30: ='Data Sheet'!I57 -> 157.2 | ... L30: ='Data Sheet'!K57 -> 157.2
B31: Reserves | C31: ='Data Sheet'!B58 -> 30465 | D31: ='Data Sheet'!C58 -> 36924.1 | E31: ='Data Sheet'!D58 -> 42408.4 | F31: ='Data Sheet'!E58 -> 46941.1 | G31: ='Data Sheet'!F58 -> 49262 | H31: ='Data Sheet'!G58 -> 52349.6 | I31: ='Data Sheet'!H58 -> 55182.5 | J31: ='Data Sheet'!I58 -> 74443 | ... L31: ='Data Sheet'!K58 -> 96082.7
B32: Borrowings | C32: ='Data Sheet'!B59 -> 230.9 | D32: ='Data Sheet'!C59 -> 483.6 | E32: ='Data Sheet'!D59 -> 120.8 | F32: ='Data Sheet'!E59 -> 159.6 | G32: ='Data Sheet'!F59 -> 184.1 | H32: ='Data Sheet'!G59 -> 540.9 | I32: ='Data Sheet'!H59 -> 425.5 | J32: ='Data Sheet'!I59 -> 1247.6 | ... L32: ='Data Sheet'!K59 -> 87
B33: Other Liabilities | C33: ='Data Sheet'!B60 -> 11878.6 | D33: ='Data Sheet'!C60 -> 14401.8 | E33: ='Data Sheet'!D60 -> 17568.2 | F33: ='Data Sheet'!E60 -> 16717 | G33: ='Data Sheet'!F60 -> 14030.6 | H33: ='Data Sheet'!G60 -> 18334.6 | I33: ='Data Sheet'!H60 -> 18896.5 | J33: ='Data Sheet'!I60 -> 24258.2 | ... L33: ='Data Sheet'!K60 -> 35644.9
B34: Total Liabilities | C34: =SUM(C30:C33) -> 42725.5 | D34: =SUM(D30:D33) -> 51960.5 | E34: =SUM(E30:E33) -> 60248.4 | F34: =SUM(F30:F33) -> 63968.7 | G34: =SUM(G30:G33) -> 63627.7 | H34: =SUM(H30:H33) -> 71376.1 | I34: =SUM(I30:I33) -> 74655.5 | J34: =SUM(J30:J33) -> 100106 | ... L34: =SUM(L30:L33) -> 131971.8
B36: Fixed Assets Net Block | C36: ='Data Sheet'!B62 -> 12529.6 | D36: ='Data Sheet'!C62 -> 13310.7 | E36: ='Data Sheet'!D62 -> 13388.8 | F36: ='Data Sheet'!E62 -> 15437.3 | G36: ='Data Sheet'!F62 -> 15744.4 | H36: ='Data Sheet'!G62 -> 14988.7 | I36: ='Data Sheet'!H62 -> 13747.2 | J36: ='Data Sheet'!I62 -> 27941.4 | ... L36: ='Data Sheet'!K62 -> 33384.5
B37: Capital Work in Progress | C37: ='Data Sheet'!B63 -> 1006.9 | D37: ='Data Sheet'!C63 -> 1252.3 | E37: ='Data Sheet'!D63 -> 2132.1 | F37: ='Data Sheet'!E63 -> 1606.9 | G37: ='Data Sheet'!F63 -> 1415.2 | H37: ='Data Sheet'!G63 -> 1496.8 | I37: ='Data Sheet'!H63 -> 2936.5 | J37: ='Data Sheet'!I63 -> 4143 | ... L37: ='Data Sheet'!K63 -> 7527.2
B38: Investments | C38: ='Data Sheet'!B64 -> 20675.8 | D38: ='Data Sheet'!C64 -> 29150.6 | E38: ='Data Sheet'!D64 -> 36123.1 | F38: ='Data Sheet'!E64 -> 37503.6 | G38: ='Data Sheet'!F64 -> 37488 | H38: ='Data Sheet'!G64 -> 42944.8 | I38: ='Data Sheet'!H64 -> 42034.7 | J38: ='Data Sheet'!I64 -> 49184.3 | ... L38: ='Data Sheet'!K64 -> 66265.4
B39: Other Assets | C39: ='Data Sheet'!B65 -> 8513.2 | D39: ='Data Sheet'!C65 -> 8246.9 | E39: ='Data Sheet'!D65 -> 8604.4 | F39: ='Data Sheet'!E65 -> 9420.9 | G39: ='Data Sheet'!F65 -> 8980.1 | H39: ='Data Sheet'!G65 -> 11945.8 | I39: ='Data Sheet'!H65 -> 15937.1 | J39: ='Data Sheet'!I65 -> 18837.3 | ... L39: ='Data Sheet'!K65 -> 24794.7
B40: Total Non-current Assets | C40: =SUM(C36:C39) -> 42725.5 | D40: =SUM(D36:D39) -> 51960.5 | E40: =SUM(E36:E39) -> 60248.4 | F40: =SUM(F36:F39) -> 63968.7 | G40: =SUM(G36:G39) -> 63627.7 | H40: =SUM(H36:H39) -> 71376.1 | I40: =SUM(I36:I39) -> 74655.5 | J40: =SUM(J36:J39) -> 100106 | ... L40: =SUM(L36:L39) -> 131971.8
B42: Receivables | C42: ='Data Sheet'!B67 -> 1323.4 | D42: ='Data Sheet'!C67 -> 1202.6 | E42: ='Data Sheet'!D67 -> 1465.4 | F42: ='Data Sheet'!E67 -> 2312.8 | G42: ='Data Sheet'!F67 -> 1977.7 | H42: ='Data Sheet'!G67 -> 1279.9 | I42: ='Data Sheet'!H67 -> 2034.5 | J42: ='Data Sheet'!I67 -> 3284.8 | ... L42: ='Data Sheet'!K67 -> 6539.7
B43: Inventory | C43: ='Data Sheet'!B68 -> 3132.6 | D43: ='Data Sheet'!C68 -> 3263.7 | E43: ='Data Sheet'!D68 -> 3160.2 | F43: ='Data Sheet'!E68 -> 3322.6 | G43: ='Data Sheet'!F68 -> 3213.9 | H43: ='Data Sheet'!G68 -> 3049 | I43: ='Data Sheet'!H68 -> 3532.3 | J43: ='Data Sheet'!I68 -> 5443.5 | ... L43: ='Data Sheet'!K68 -> 6913.2
B44: Cash & Bank | C44: ='Data Sheet'!B69 -> 50.7 | D44: ='Data Sheet'!C69 -> 23.5 | E44: ='Data Sheet'!D69 -> 74 | F44: ='Data Sheet'!E69 -> 187.8 | G44: ='Data Sheet'!F69 -> 29 | H44: ='Data Sheet'!G69 -> 3047.1 | I44: ='Data Sheet'!H69 -> 3042.2 | J44: ='Data Sheet'!I69 -> 2748.5 | ... L44: ='Data Sheet'!K69 -> 552.9
B45: Total Current Assets | C45: =SUM(C42:C44) -> 4506.7 | D45: =SUM(D42:D44) -> 4489.8 | E45: =SUM(E42:E44) -> 4699.6 | F45: =SUM(F42:F44) -> 5823.2 | G45: =SUM(G42:G44) -> 5220.6 | H45: =SUM(H42:H44) -> 7376 | I45: =SUM(I42:I44) -> 8609 | J45: =SUM(J42:J44) -> 11476.8 | ... L45: =SUM(L42:L44) -> 14005.8
B47: Total Assets | C47: =SUM(C40,C45) -> 47232.2 | D47: =SUM(D40,D45) -> 56450.3 | E47: =SUM(E40,E45) -> 64948 | F47: =SUM(F40,F45) -> 69791.9 | G47: =SUM(G40,G45) -> 68848.3 | H47: =SUM(H40,H45) -> 78752.1 | I47: =SUM(I40,I45) -> 83264.5 | J47: =SUM(J40,J45) -> 111582.8 | ... L47: =SUM(L40,L45) -> 145977.6
B49: ="Cash Flow Statement"&" - "&B1 -> Cash Flow Statement - MARUTI SUZUKI LTD
B50: Operating Activities
...

Sheet Comparative Analysis
C2: ="Comparative Analysis"&" - "&'Historical Financials'!B1 -> Comparative Analysis - MARUTI SUZUKI LTD
B3: Year | C3: 2016 | D3: =C3+1 -> 2017 | E3: =D3+1 -> 2018 | F3: =E3+1 -> 2019 | G3: =F3+1 -> 2020 | H3: =G3+1 -> 2021 | I3: =H3+1 -> 2022 | J3: =I3+1 -> 2023 | K3: =J3+1 -> 2024 | L3: =K3+1 -> 2025
B5: Income Statement
B6: Sales | C6: =IFERROR(('Historical Financials'!C7-'Historical Financials'!B7)/'Historical Financials'!B7,"-") -> - | D6: =('Historical Financials'!D7-'Historical Financials'!C7)/'Historical Financials'!C7 -> 0.18225703 | E6: =('Historical Financials'!E7-'Historical Financials'!D7)/'Historical Financials'!D7 -> 0.17220239 | F6: =('Historical Financials'!F7-'Historical Financials'!E7)/'Historical Financials'!E7 -> 0.078425599 | G6: =('Historical Financials'!G7-'Historical Financials'!F7)/'Historical Financials'!F7 -> -0.12093275 | H6: =('Historical Financials'!H7-'Historical Financials'!G7)/'Historical Financials'!G7 -> -0.06989162 | I6: =('Historical Financials'!I7-'Historical Financials'!H7)/'Historical Financials'!H7 -> 0.25518388 | J6: =('Historical Financials'!J7-'Historical Financials'!I7)/'Historical Financials'!I7 -> 0.34054306 | K6: =('Historical Financials'!K7-'Historical Financials'!J7)/'Historical Financials'!J7 -> 0.19802652 | L6: =('Historical Financials'!L7-'Historical Financials'!K7)/'Historical Financials'!K7 -> 0.077928523
B7: COGS | C7: =IFERROR(('Historical Financials'!C8-'Historical Financials'!B8)/'Historical Financials'!B8,"-") -> - | D7: =('Historical Financials'!D8-'Historical Financials'!C8)/'Historical Financials'!C8 -> 0.19546144 | E7: =('Historical Financials'!E8-'Historical Financials'!D8)/'Historical Financials'!D8 -> 0.17960563 | F7: =('Historical Financials'!F8-'Historical Financials'!E8)/'Historical Financials'!E8 -> 0.088110537 | G7: =('Historical Financials'!G8-'Historical Financials'!F8)/'Historical Financials'!F8 -> -0.10166526 | H7: =('Historical Financials'!H8-'Historical Financials'!G8)/'Historical Financials'!G8 -> -0.038876392 | I7: =('Historical Financials'!I8-'Historical Financials'!H8)/'Historical Financials'!H8 -> 0.29167238 | J7: =('Historical Financials'!J8-'Historical Financials'!I8)/'Historical Financials'!I8 -> 0.2955037 | K7: =('Historical Financials'!K8-'Historical Financials'!J8)/'Historical Financials'!J8 -> 0.16482801 | L7: =('Historical Financials'!L8-'Historical Financials'!K8)/'Historical Financials'!K8 -> 0.060191529
B8: Gross Profit | C8: =IFERROR(('Historical Financials'!C9-'Historical Financials'!B9)/'Historical Financials'!B9,"-") -> - | D8: =('Historical Financials'!D9-'Historical Financials'!C9)/'Historical Financials'!C9 -> 0.14721334 | E8: =('Historical Financials'!E9-'Historical Financials'!D9)/'Historical Financials'!D9 -> 0.15172833 | F8: =('Historical Financials'!F9-'Historical Financials'!E9)/'Historical Financials'!E9 -> 0.050993066 | G8: =('Historical Financials'!G9-'Historical Financials'!F9)/'Historical Financials'!F9 -> -0.1774352 | H8: =('Historical Financials'!H9-'Historical Financials'!G9)/'Historical Financials'!G9 -> -0.16922274 | I8: =('Historical Financials'!I9-'Historical Financials'!H9)/'Historical Financials'!H9 -> 0.11998877 | J8: =('Historical Financials'!J9-'Historical Financials'!I9)/'Historical Financials'!I9 -> 0.53300101 | K8: =('Historical Financials'!K9-'Historical Financials'!J9)/'Historical Financials'!J9 -> 0.31790976 | L8: =('Historical Financials'!L9-'Historical Financials'!K9)/'Historical Financials'!K9 -> 0.1345389
B9: Selling & General Expenses | C9: =IFERROR(('Historical Financials'!C10-'Historical Financials'!B10)/'Historical Financials'!B10,"-") -> - | D9: =('Historical Financials'!D10-'Historical Financials'!C10)/'Historical Financials'!C9 -> 0.058563017 | E9: =('Historical Financials'!E10-'Historical Financials'!D10)/'Historical Financials'!D9 -> 0.057895028 | F9: =('Historical Financials'!F10-'Historical Financials'!E10)/'Historical Financials'!E9 -> 0.10197173 | G9: =('Historical Financials'!G10-'Historical Financials'!F10)/'Historical Financials'!F9 -> -0.0083202734 | H9: =('Historical Financials'!H10-'Historical Financials'!G10)/'Historical Financials'!G9 -> -0.061217915 | I9: =('Historical Financials'!I10-'Historical Financials'!H10)/'Historical Financials'!H9 -> 0.097162419 | J9: =('Historical Financials'!J10-'Historical Financials'!I10)/'Historical Financials'!I9 -> 0.093057131 | K9: =('Historical Financials'!K10-'Historical Financials'!J10)/'Historical Financials'!J9 -> 0.10354254 | L9: =('Historical Financials'!L10-'Historical Financials'!K10)/'Historical Financials'!K9 -> 0.089330142
B10: EBITDA | C10: =IFERROR(('Historical Financials'!C11-'Historical Financials'!B11)/'Historical Financials'!B11,"-") -> - | D10: =('Historical Financials'!D11-'Historical Financials'!C11)/'Historical Financials'!C11 -> 0.15482984 | E10: =('Historical Financials'!E11-'Historical Financials'!D11)/'Historical Financials'!D11 -> 0.16280119 | F10: =('Historical Financials'!F11-'Historical Financials'!E11)/'Historical Financials'!E11 -> -0.087605938 | G10: =('Historical Financials'!G11-'Historical Financials'!F11)/'Historical Financials'!F11 -> -0.33476841 | H10: =('Historical Financials'!H11-'Historical Financials'!G11)/'Historical Financials'!G11 -> -0.26436438 | I10: =('Historical Financials'!I11-'Historical Financials'!H11)/'Historical Financials'!H11 -> 0.063098362 | J10: =('Historical Financials'!J11-'Historical Financials'!I11)/'Historical Financials'!I11 -> 1.2812065 | K10: =('Historical Financials'!K11-'Historical Financials'!J11)/'Historical Financials'!J11 -> 0.41952521 | L10: =('Historical Financials'!L11-'Historical Financials'!K11)/'Historical Financials'!K11 -> 0.082141918
B11: Depreciation | C11: =IFERROR(('Historical Financials'!C12-'Historical Financials'!B12)/'Historical Financials'!B12,"-") -> - | D11: =('Historical Financials'!D12-'Historical Financials'!C12)/'Historical Financials'!C12 -> -0.077220214 | E11: =('Historical Financials'!E12-'Historical Financials'!D12)/'Historical Financials'!D12 -> 0.059871731 | F11: =('Historical Financials'!F12-'Historical Financials'!E12)/'Historical Financials'!E12 -> 0.09457207 | G11: =('Historical Financials'!G12-'Historical Financials'!F12)/'Historical Financials'!F12 -> 0.16803496 | H11: =('Historical Financials'!H12-'Historical Financials'!G12)/'Historical Financials'!G12 -> -0.14009183 | I11: =('Historical Financials'!I12-'Historical Financials'!H12)/'Historical Financials'!H12 -> -0.08078178 | J11: =('Historical Financials'!J12-'Historical Financials'!I12)/'Historical Financials'!I12 -> 0.73754034 | K11: =('Historical Financials'!K12-'Historical Financials'!J12)/'Historical Financials'!J12 -> 0.084564589 | L11: =('Historical Financials'!L12-'Historical Financials'!K12)/'Historical Financials'!K12 -> 0.067049736
B12: EBIT | C12: =IFERROR(('Historical Financials'!C13-'Historical Financials'!B13)/'Historical Financials'!B13,"-") -> - | D12: =('Historical Financials'!D13-'Historical Financials'!C13)/'Historical Financials'!C13 -> 0.2604034 | E12: =('Historical Financials'!E13-'Historical Financials'!D13)/'Historical Financials'!D13 -> 0.19708599 | F12: =('Historical Financials'!F13-'Historical Financials'!E13)/'Historical Financials'!E13 -> -0.14133211 | G12: =('Historical Financials'!G13-'Historical Financials'!F13)/'Historical Financials'!F13 -> -0.52378819 | H12: =('Historical Financials'!H13-'Historical Financials'!G13)/'Historical Financials'!G13 -> -0.37895259 | I12: =('Historical Financials'!I13-'Historical Financials'!H13)/'Historical Financials'!H13 -> 0.2467915 | J12: =('Historical Financials'!J13-'Historical Financials'!I13)/'Historical Financials'!I13 -> 1.7929463 | K12: =('Historical Financials'!K13-'Historical Financials'!J13)/'Historical Financials'!J13 -> 0.61567277 | L12: =('Historical Financials'!L13-'Historical Financials'!K13)/'Historical Financials'!K13 -> 0.088074492
B13: Interest | C13: =IFERROR(('Historical Financials'!C14-'Historical Financials'!B14)/'Historical Financials'!B14,"-") -> - | D13: =('Historical Financials'!D14-'Historical Financials'!C14)/'Historical Financials'!C14 -> 0.094247246 | E13: =('Historical Financials'!E14-'Historical Financials'!D14)/'Historical Financials'!D14 -> 2.8680089 | F13: =('Historical Financials'!F14-'Historical Financials'!E14)/'Historical Financials'!E14 -> -0.78050896 | G13: =('Historical Financials'!G14-'Historical Financials'!F14)/'Historical Financials'!F14 -> 0.76811594 | H13: =('Historical Financials'!H14-'Historical Financials'!G14)/'Historical Financials'!G14 -> -0.2414307 | I13: =('Historical Financials'!I14-'Historical Financials'!H14)/'Historical Financials'!H14 -> 0.24361493 | J13: =('Historical Financials'!J14-'Historical Financials'!I14)/'Historical Financials'!I14 -> 0.992891 | K13: =('Historical Financials'!K14-'Historical Financials'!J14)/'Historical Financials'!J14 -> -0.23265953 | L13: =('Historical Financials'!L14-'Historical Financials'!K14)/'Historical Financials'!K14 -> 0.0030991736
B14: Other Income | C14: =IFERROR(('Historical Financials'!C15-'Historical Financials'!B15)/'Historical Financials'!B15,"-") -> - | D14: =('Historical Financials'!D15-'Historical Financials'!C15)/'Historical Financials'!C15 -> 0.63868588 | E14: =('Historical Financials'!E15-'Historical Financials'!D15)/'Historical Financials'!D15 -> -0.10195065 | F14: =('Historical Financials'!F15-'Historical Financials'!E15)/'Historical Financials'!E15 -> 0.23651722 | G14: =('Historical Financials'!G15-'Historical Financials'!F15)/'Historical Financials'!F15 -> 0.28008408 | H14: =('Historical Financials'!H15-'Historical Financials'!G15)/'Historical Financials'!G15 -> -0.10676167 | I14: =('Historical Financials'!I15-'Historical Financials'!H15)/'Historical Financials'!H15 -> -0.38916062 | J14: =('Historical Financials'!J15-'Historical Financials'!I15)/'Historical Financials'!I15 -> 0.29782889 | K14: =('Historical Financials'!K15-'Historical Financials'!J15)/'Historical Financials'!J15 -> 0.75884058 | L14: =('Historical Financials'!L15-'Historical Financials'!K15)/'Historical Financials'!K15 -> 0.23978247
B15: EBT | C15: =IFERROR(('Historical Financials'!C16-'Historical Financials'!B16)/'Historical Financials'!B16,"-") -> - | D15: =('Historical Financials'!D16-'Historical Financials'!C16)/'Historical Financials'!C16 -> 0.14437883 | E15: =('Historical Financials'!E16-'Historical Financials'!D16)/'Historical Financials'!D16 -> 0.28691263 | F15: =('Historical Financials'!F16-'Historical Financials'!E16)/'Historical Financials'!E16 -> -0.22781691 | G15: =('Historical Financials'!G16-'Historical Financials'!F16)/'Historical Financials'!F16 -> -0.94674623 | H15: =('Historical Financials'!H16-'Historical Financials'!G16)/'Historical Financials'!G16 -> -3.7361702 | I15: =('Historical Financials'!I16-'Historical Financials'!H16)/'Historical Financials'!H16 -> -2.2643857 | J15: =('Historical Financials'!J16-'Historical Financials'!I16)/'Historical Financials'!I16 -> 4.7484625 | K15: =('Historical Financials'!K16-'Historical Financials'!J16)/'Historical Financials'!J16 -> 0.59218644 | L15: =('Historical Financials'!L16-'Historical Financials'!K16)/'Historical Financials'!K16 -> 0.017750552
B16: Tax | C16: =IFERROR(('Historical Financials'!C17-'Historical Financials'!B17)/'Historical Financials'!B17,"-") -> - | D16: =('Historical Financials'!D17-'Historical Financials'!C17)/'Historical Financials'!C17 -> 0.25326946 | E16: =('Historical Financials'!E17-'Historical Financials'!D17)/'Historical Financials'!D17 -> 0.25609663 | F16: =('Historical Financials'!F17-'Historical Financials'!E17)/'Historical Financials'!E17 -> -0.09524679 | G16: =('Historical Financials'!G17-'Historical Financials'!F17)/'Historical Financials'!F17 -> -0.52065115 | H16: =('Historical Financials'!H17-'Historical Financials'!G17)/'Historical Financials'!G17 -> -0.34612686 | I16: =('Historical Financials'!I17-'Historical Financials'!H17)/'Historical Financials'!H17 -> -0.12254534 | J16: =('Historical Financials'!J17-'Historical Financials'!I17)/'Historical Financials'!I17 -> 1.6592882 | K16: =('Historical Financials'!K17-'Historical Financials'!J17)/'Historical Financials'!J17 -> 0.81020924 | L16: =('Historical Financials'!L17-'Historical Financials'!K17)/'Historical Financials'!K17 -> 0.30066306
B17: Net Income | C17: =IFERROR(('Historical Financials'!C18-'Historical Financials'!B18)/'Historical Financials'!B18,"-") -> - | D17: =('Historical Financials'!D18-'Historical Financials'!C18)/'Historical Financials'!C18 -> 0.055897236 | E17: =('Historical Financials'!E18-'Historical Financials'!D18)/'Historical Financials'!D18 -> 0.31663349 | F17: =('Historical Financials'!F18-'Historical Financials'!E18)/'Historical Financials'!E18 -> -0.349797 | G17: =('Historical Financials'!G18-'Historical Financials'!F18)/'Historical Financials'!F18 -> -1.4922918 | H17: =('Historical Financials'!H18-'Historical Financials'!G18)/'Historical Financials'!G18 -> 0.49011547 | I17: =('Historical Financials'!I18-'Historical Financials'!H18)/'Historical Financials'!H18 -> -1.0926915 | J17: =('Historical Financials'!J18-'Historical Financials'!I18)/'Historical Financials'!I18 -> 20.746042 | K17: =('Historical Financials'!K18-'Historical Financials'!J18)/'Historical Financials'!J18 -> 0.45411655 | L17: =('Historical Financials'!L18-'Historical Financials'!K18)/'Historical Financials'!K18 -> -0.2052874
B19: Balance Sheet
B20: Equity Share Capital | D20: =('Historical Financials'!D30-'Historical Financials'!C30)/'Historical Financials'!C30 -> 0 | E20: =('Historical Financials'!E30-'Historical Financials'!D30)/'Historical Financials'!D30 -> 0 | F20: =('Historical Financials'!F30-'Historical Financials'!E30)/'Historical Financials'!E30 -> 0 | G20: =('Historical Financials'!G30-'Historical Financials'!F30)/'Historical Financials'!F30 -> 0 | H20: =('Historical Financials'!H30-'Historical Financials'!G30)/'Historical Financials'!G30 -> 0 | I20: =('Historical Financials'!I30-'Historical Financials'!H30)/'Historical Financials'!H30 -> 0 | J20: =('Historical Financials'!J30-'Historical Financials'!I30)/'Historical Financials'!I30 -> 0.041059603 | K20: =('Historical Financials'!K30-'Historical Financials'!J30)/'Historical Financials'!J30 -> 0 | L20: =('Historical Financials'!L30-'Historical Financials'!K30)/'Historical Financials'!K30 -> 0
B21: Reserves | D21: =('Historical Financials'!D31-'Historical Financials'!C31)/'Historical Financials'!C31 -> 0.21201707 | E21: =('Historical Financials'!E31-'Historical Financials'!D31)/'Historical Financials'!D31 -> 0.14852901 | F21: =('Historical Financials'!F31-'Historical Financials'!E31)/'Historical Financials'!E31 -> 0.10688213 | G21: =('Historical Financials'!G31-'Historical Financials'!F31)/'Historical Financials'!F31 -> 0.049442812 | H21: =('Historical Financials'!H31-'Historical Financials'!G31)/'Historical Financials'!G31 -> 0.062677114 | I21: =('Historical Financials'!I31-'Historical Financials'!H31)/'Historical Financials'!H31 -> 0.054115027 | J21: =('Historical Financials'!J31-'Historical Financials'!I31)/'Historical Financials'!I31 -> 0.34903275 | K21: =('Historical Financials'!K31-'Historical Financials'!J31)/'Historical Financials'!J31 -> 0.14824497 | L21: =('Historical Financials'!L31-'Historical Financials'!K31)/'Historical Financials'!K31 -> 0.12405298
B22: Borrowings | D22: =('Historical Financials'!D32-'Historical Financials'!C32)/'Historical Financials'!C32 -> 1.0944132 | E22: =('Historical Financials'!E32-'Historical Financials'!D32)/'Historical Financials'!D32 -> -0.75020678 | F22: =('Historical Financials'!F32-'Historical Financials'!E32)/'Historical Financials'!E32 -> 0.32119205 | G22: =('Historical Financials'!G32-'Historical Financials'!F32)/'Historical Financials'!F32 -> 0.15350877 | H22: =('Historical Financials'!H32-'Historical Financials'!G32)/'Historical Financials'!G32 -> 1.9380771 | I22: =('Historical Financials'!I32-'Historical Financials'!H32)/'Historical Financials'!H32 -> -0.21334812 | J22: =('Historical Financials'!J32-'Historical Financials'!I32)/'Historical Financials'!I32 -> 1.9320799 | K22: =('Historical Financials'!K32-'Historical Financials'!J32)/'Historical Financials'!J32 -> -0.90493748 | L22: =('Historical Financials'!L32-'Historical Financials'!K32)/'Historical Financials'!K32 -> -0.26644182
B23: Other Liabilities | D23: =('Historical Financials'!D33-'Historical Financials'!C33)/'Historical Financials'!C33 -> 0.2124156 | E23: =('Historical Financials'!E33-'Historical Financials'!D33)/'Historical Financials'!D33 -> 0.21986141 | F23: =('Historical Financials'!F33-'Historical Financials'!E33)/'Historical Financials'!E33 -> -0.048451179 | G23: =('Historical Financials'!G33-'Historical Financials'!F33)/'Historical Financials'!F33 -> -0.16069869 | H23: =('Historical Financials'!H33-'Historical Financials'!G33)/'Historical Financials'!G33 -> 0.30675809 | I23: =('Historical Financials'!I33-'Historical Financials'!H33)/'Historical Financials'!H33 -> 0.030646973 | J23: =('Historical Financials'!J33-'Historical Financials'!I33)/'Historical Financials'!I33 -> 0.28374038 | K23: =('Historical Financials'!K33-'Historical Financials'!J33)/'Historical Financials'!J33 -> 0.21812418 | L23: =('Historical Financials'!L33-'Historical Financials'!K33)/'Historical Financials'!K33 -> 0.2062776
B24: Total Liabilities | D24: =('Historical Financials'!D34-'Historical Financials'!C34)/'Historical Financials'!C34 -> 0.21614727 | E24: =('Historical Financials'!E34-'Historical Financials'!D34)/'Historical Financials'!D34 -> 0.15950385 | F24: =('Historical Financials'!F34-'Historical Financials'!E34)/'Historical Financials'!E34 -> 0.061749358 | G24: =('Historical Financials'!G34-'Historical Financials'!F34)/'Historical Financials'!F34 -> -0.0053307321 | H24: =('Historical Financials'!H34-'Historical Financials'!G34)/'Historical Financials'!G34 -> 0.12177715 | I24: =('Historical Financials'!I34-'Historical Financials'!H34)/'Historical Financials'!H34 -> 0.045945351 | J24: =('Historical Financials'!J34-'Historical Financials'!I34)/'Historical Financials'!I34 -> 0.34090589 | K24: =('Historical Financials'!K34-'Historical Financials'!J34)/'Historical Financials'!J34 -> 0.15182007 | L24: =('Historical Financials'!L34-'Historical Financials'!K34)/'Historical Financials'!K34 -> 0.14455427
B26: Fixed Assets Net Block | D26: =('Historical Financials'!D36-'Historical Financials'!C36)/'Historical Financials'!C36 -> 0.062340378 | E26: =('Historical Financials'!E36-'Historical Financials'!D36)/'Historical Financials'!D36 -> 0.00586746 | F26: =('Historical Financials'!F36-'Historical Financials'!E36)/'Historical Financials'!E36 -> 0.15300102 | G26: =('Historical Financials'!G36-'Historical Financials'!F36)/'Historical Financials'!F36 -> 0.019893375 | H26: =('Historical Financials'!H36-'Historical Financials'!G36)/'Historical Financials'!G36 -> -0.047998018 | I26: =('Historical Financials'!I36-'Historical Financials'!H36)/'Historical Financials'!H36 -> -0.082829065 | J26: =('Historical Financials'!J36-'Historical Financials'!I36)/'Historical Financials'!I36 -> 1.0325157 | K26: =('Historical Financials'!K36-'Historical Financials'!J36)/'Historical Financials'!J36 -> -0.0027414518 | L26: =('Historical Financials'!L36-'Historical Financials'!K36)/'Historical Financials'!K36 -> 0.19808863
B27: Capital Work in Progress | D27: =('Historical Financials'!D37-'Historical Financials'!C37)/'Historical Financials'!C37 -> 0.24371834 | E27: =('Historical Financials'!E37-'Historical Financials'!D37)/'Historical Financials'!D37 -> 0.70254731 | F27: =('Historical Financials'!F37-'Historical Financials'!E37)/'Historical Financials'!E37 -> -0.24632991 | G27: =('Historical Financials'!G37-'Historical Financials'!F37)/'Historical Financials'!F37 -> -0.11929803 | H27: =('Historical Financials'!H37-'Historical Financials'!G37)/'Historical Financials'!G37 -> 0.057659695 | I27: =('Historical Financials'!I37-'Historical Financials'!H37)/'Historical Financials'!H37 -> 0.96185195 | J27: =('Historical Financials'!J37-'Historical Financials'!I37)/'Historical Financials'!I37 -> 0.41086327 | K27: =('Historical Financials'!K37-'Historical Financials'!J37)/'Historical Financials'!J37 -> 0.86695631 | L27: =('Historical Financials'!L37-'Historical Financials'!K37)/'Historical Financials'!K37 -> -0.026839737
B28: Investments | D28: =('Historical Financials'!D38-'Historical Financials'!C38)/'Historical Financials'!C38 -> 0.40988982 | E28: =('Historical Financials'!E38-'Historical Financials'!D38)/'Historical Financials'!D38 -> 0.2391889 | F28: =('Historical Financials'!F38-'Historical Financials'!E38)/'Historical Financials'!E38 -> 0.038216543 | G28: =('Historical Financials'!G38-'Historical Financials'!F38)/'Historical Financials'!F38 -> -0.00041596007 | H28: =('Historical Financials'!H38-'Historical Financials'!G38)/'Historical Financials'!G38 -> 0.14556125 | I28: =('Historical Financials'!I38-'Historical Financials'!H38)/'Historical Financials'!H38 -> -0.021192321 | J28: =('Historical Financials'!J38-'Historical Financials'!I38)/'Historical Financials'!I38 -> 0.17008805 | K28: =('Historical Financials'!K38-'Historical Financials'!J38)/'Historical Financials'!J38 -> 0.16492458 | L28: =('Historical Financials'!L38-'Historical Financials'!K38)/'Historical Financials'!K38 -> 0.15654496
B29: Other Assets | D29: =('Historical Financials'!D39-'Historical Financials'!C39)/'Historical Financials'!C39 -> -0.031280834 | E29: =('Historical Financials'!E39-'Historical Financials'!D39)/'Historical Financials'!D39 -> 0.043349622 | F29: =('Historical Financials'!F39-'Historical Financials'!E39)/'Historical Financials'!E39 -> 0.09489331 | G29: =('Historical Financials'!G39-'Historical Financials'!F39)/'Historical Financials'!F39 -> -0.046789585 | H29: =('Historical Financials'!H39-'Historical Financials'!G39)/'Historical Financials'!G39 -> 0.33025245 | I29: =('Historical Financials'!I39-'Historical Financials'!H39)/'Historical Financials'!H39 -> 0.33411743 | J29: =('Historical Financials'!J39-'Historical Financials'!I39)/'Historical Financials'!I39 -> 0.1819779 | K29: =('Historical Financials'!K39-'Historical Financials'!J39)/'Historical Financials'!J39 -> 0.18958131 | L29: =('Historical Financials'!L39-'Historical Financials'!K39)/'Historical Financials'!K39 -> 0.10648638
B30: Total Non-current Assets | D30: =('Historical Financials'!D40-'Historical Financials'!C40)/'Historical Financials'!C40 -> 0.21614727 | E30: =('Historical Financials'!E40-'Historical Financials'!D40)/'Historical Financials'!D40 -> 0.15950385 | F30: =('Historical Financials'!F40-'Historical Financials'!E40)/'Historical Financials'!E40 -> 0.061749358 | G30: =('Historical Financials'!G40-'Historical Financials'!F40)/'Historical Financials'!F40 -> -0.0053307321 | H30: =('Historical Financials'!H40-'Historical Financials'!G40)/'Historical Financials'!G40 -> 0.12177715 | I30: =('Historical Financials'!I40-'Historical Financials'!H40)/'Historical Financials'!H40 -> 0.045945351 | J30: =('Historical Financials'!J40-'Historical Financials'!I40)/'Historical Financials'!I40 -> 0.34090589 | K30: =('Historical Financials'!K40-'Historical Financials'!J40)/'Historical Financials'!J40 -> 0.15182007 | L30: =('Historical Financials'!L40-'Historical Financials'!K40)/'Historical Financials'!K40 -> 0.14455427
B32: Receivables | D32: =('Historical Financials'!D42-'Historical Financials'!C42)/'Historical Financials'!C42 -> -0.091280036 | E32: =('Historical Financials'!E42-'Historical Financials'!D42)/'Historical Financials'!D42 -> 0.21852653 | F32: =('Historical Financials'!F42-'Historical Financials'!E42)/'Historical Financials'!E42 -> 0.57827214 | G32: =('Historical Financials'!G42-'Historical Financials'!F42)/'Historical Financials'!F42 -> -0.14488931 | H32: =('Historical Financials'!H42-'Historical Financials'!G42)/'Historical Financials'!G42 -> -0.3528341 | I32: =('Historical Financials'!I42-'Historical Financials'!H42)/'Historical Financials'!H42 -> 0.58957731 | J32: =('Historical Financials'!J42-'Historical Financials'!I42)/'Historical Financials'!I42 -> 0.61454903 | K32: =('Historical Financials'!K42-'Historical Financials'!J42)/'Historical Financials'!J42 -> 0.39941549 | L32: =('Historical Financials'!L42-'Historical Financials'!K42)/'Historical Financials'!K42 -> 0.42266359
B33: Inventory | D33: =('Historical Financials'!D43-'Historical Financials'!C43)/'Historical Financials'!C43 -> 0.04185022 | E33: =('Historical Financials'!E43-'Historical Financials'!D43)/'Historical Financials'!D43 -> -0.031712474 | F33: =('Historical Financials'!F43-'Historical Financials'!E43)/'Historical Financials'!E43 -> 0.051389153 | G33: =('Historical Financials'!G43-'Historical Financials'!F43)/'Historical Financials'!F43 -> -0.032715343 | H33: =('Historical Financials'!H43-'Historical Financials'!G43)/'Historical Financials'!G43 -> -0.051308379 | I33: =('Historical Financials'!I43-'Historical Financials'!H43)/'Historical Financials'!H43 -> 0.15851099 | J33: =('Historical Financials'!J43-'Historical Financials'!I43)/'Historical Financials'!I43 -> 0.5410639 | K33: =('Historical Financials'!K43-'Historical Financials'!J43)/'Historical Financials'!J43 -> -0.023036649 | L33: =('Historical Financials'!L43-'Historical Financials'!K43)/'Historical Financials'!K43 -> 0.29993795
... B37: Total Assets | D37: =('Historical Financials'!D47-'Historical Financials'!C47)/'Historical Financials'!C47 -> 0.19516559 | E37: =('Historical Financials'!E47-'Historical Financials'!D47)/'Historical Financials'!D47 -> 0.15053419 | F37: =('Historical Financials'!F47-'Historical Financials'!E47)/'Historical Financials'!E47 -> 0.074581203 | G37: =('Historical Financials'!G47-'Historical Financials'!F47)/'Historical Financials'!F47 -> -0.013520194 | H37: =('Historical Financials'!H47-'Historical Financials'!G47)/'Historical Financials'!G47 -> 0.14384959 | I37: =('Historical Financials'!I47-'Historical Financials'!H47)/'Historical Financials'!H47 -> 0.057298789 | J37: =('Historical Financials'!J47-'Historical Financials'!I47)/'Historical Financials'!I47 -> 0.34010052 | K37: =('Historical Financials'!K47-'Historical Financials'!J47)/'Historical Financials'!J47 -> 0.14754604 | L37: =('Historical Financials'!L47-'Historical Financials'!K47)/'Historical Financials'!K47 -> 0.14003674
B39: Cash Flow Statement
B40: Operating Activities
B41: Profit From Operations | D41: =('Historical Financials'!D51-'Historical Financials'!C51)/'Historical Financials'!C51 -> 0.32635492 | E41: =('Historical Financials'!E51-'Historical Financials'!D51)/'Historical Financials'!D51 -> 0.31804101 | F41: =('Historical Financials'!F51-'Historical Financials'!E51)/'Historical Financials'!E51 -> 0.1654169 | G41: =('Historical Financials'!G51-'Historical Financials'!F51)/'Historical Financials'!F51 -> 0.15586286 | H41: =('Historical Financials'!H51-'Historical Financials'!G51)/'Historical Financials'!G51 -> -0.081090063 | I41: =('Historical Financials'!I51-'Historical Financials'!H51)/'Historical Financials'!H51 -> -0.3216094 | J41: =('Historical Financials'!J51-'Historical Financials'!I51)/'Historical Financials'!I51 -> -0.2628282 | K41: =('Historical Financials'!K51-'Historical Financials'!J51)/'Historical Financials'!J51 -> 0.054420539 | L41: =('Historical Financials'!L51-'Historical Financials'!K51)/'Historical Financials'!K51 -> 1.2592593
B42: Receivables | D42: =('Historical Financials'!D52-'Historical Financials'!C52)/'Historical Financials'!C52 -> 6.5 | E42: =('Historical Financials'!E52-'Historical Financials'!D52)/'Historical Financials'!D52 -> -1.5913043 | F42: =('Historical Financials'!F52-'Historical Financials'!E52)/'Historical Financials'!E52 -> -1.5980392 | G42: =('Historical Financials'!G52-'Historical Financials'!F52)/'Historical Financials'!F52 -> -3.147541 | H42: =('Historical Financials'!H52-'Historical Financials'!G52)/'Historical Financials'!G52 -> 2.2480916 | I42: =('Historical Financials'!I52-'Historical Financials'!H52)/'Historical Financials'!H52 -> -1.39953 | J42: =('Historical Financials'!J52-'Historical Financials'!I52)/'Historical Financials'!I52 -> 1.0470588 | K42: =('Historical Financials'!K52-'Historical Financials'!J52)/'Historical Financials'!J52 -> -2.0977011 | L42: =('Historical Financials'!L52-'Historical Financials'!K52)/'Historical Financials'!K52 -> 0.66230366
B43: Inventory | D43: =('Historical Financials'!D53-'Historical Financials'!C53)/'Historical Financials'!C53 -> -8.9193548 | E43: =('Historical Financials'!E53-'Historical Financials'!D53)/'Historical Financials'!D53 -> -0.54175153 | F43: =('Historical Financials'!F53-'Historical Financials'!E53)/'Historical Financials'!E53 -> -0.70888889 | G43: =('Historical Financials'!G53-'Historical Financials'!F53)/'Historical Financials'!F53 -> -1.7938931 | H43: =('Historical Financials'!H53-'Historical Financials'!G53)/'Historical Financials'!G53 -> -2.5576923 | I43: =('Historical Financials'!I53-'Historical Financials'!H53)/'Historical Financials'!H53 -> -1.6728395 | J43: =('Historical Financials'!J53-'Historical Financials'!I53)/'Historical Financials'!I53 -> 0.51376147 | K43: =('Historical Financials'!K53-'Historical Financials'!J53)/'Historical Financials'!J53 -> -3.9272727 | L43: =('Historical Financials'!L53-'Historical Financials'!K53)/'Historical Financials'!K53 -> 1.173913
B44: Payables | D44: =('Historical Financials'!D54-'Historical Financials'!C54)/'Historical Financials'!C54 -> -0.12423124 | E44: =('Historical Financials'!E54-'Historical Financials'!D54)/'Historical Financials'!D54 -> 1.5126404 | F44: =('Historical Financials'!F54-'Historical Financials'!E54)/'Historical Financials'!E54 -> -0.45276691 | G44: =('Historical Financials'!G54-'Historical Financials'!F54)/'Historical Financials'!F54 -> 1.1736466 | H44: =('Historical Financials'!H54-'Historical Financials'!G54)/'Historical Financials'!G54 -> -1.4031955 | I44: =('Historical Financials'!I54-'Historical Financials'!H54)/'Historical Financials'!H54 -> 1.511655 | J44: =('Historical Financials'!J54-'Historical Financials'!I54)/'Historical Financials'!I54 -> -2.2436195 | K44: =('Historical Financials'!K54-'Historical Financials'!J54)/'Historical Financials'!J54 -> -1.1477612 | L44: =('Historical Financials'!L54-'Historical Financials'!K54)/'Historical Financials'!K54 -> -7.290404
B45: Loan Advances | D45: =('Historical Financials'!D55-'Historical Financials'!C55)/'Historical Financials'!C55 -> -1.0408526 | E45: =('Historical Financials'!E55-'Historical Financials'!D55)/'Historical Financials'!D55 -> -1.0434783 | F45: =IFERROR(('Historical Financials'!F55-'Historical Financials'!E55)/'Historical Financials'!E55,"-") -> -2 | G45: =('Historical Financials'!G55-'Historical Financials'!F55)/'Historical Financials'!F55 -> -1 | H45: =('Historical Financials'!H55-'Historical Financials'!G55)/'Historical Financials'!G55 -> #DIV/0! | I45: =('Historical Financials'!I55-'Historical Financials'!H55)/'Historical Financials'!H55 -> -0.92307692 | J45: =('Historical Financials'!J55-'Historical Financials'!I55)/'Historical Financials'!I55 -> 5 | K45: =('Historical Financials'!K55-'Historical Financials'!J55)/'Historical Financials'!J55 -> 0.33333333 | L45: =('Historical Financials'!L55-'Historical Financials'!K55)/'Historical Financials'!K55 -> -1.125
B46: Operating Investments | D46: =IFERROR(('Historical Financials'!D56-'Historical Financials'!C56)/'Historical Financials'!C56,"-") -> - | E46: =IFERROR(('Historical Financials'!E56-'Historical Financials'!D56)/'Historical Financials'!D56,"-") -> - | F46: =IFERROR(('Historical Financials'!F56-'Historical Financials'!E56)/'Historical Financials'!E56,"-") -> - | G46: =IFERROR(('Historical Financials'!G56-'Historical Financials'!F56)/'Historical Financials'!F56,"-") -> - | H46: =IFERROR(('Historical Financials'!H56-'Historical Financials'!G56)/'Historical Financials'!G56,"-") -> - | I46: =IFERROR(('Historical Financials'!I56-'Historical Financials'!H56)/'Historical Financials'!H56,"-") -> - | J46: =IFERROR(('Historical Financials'!J56-'Historical Financials'!I56)/'Historical Financials'!I56,"-") -> - | K46: =IFERROR(('Historical Financials'!K56-'Historical Financials'!J56)/'Historical Financials'!J56,"-") -> - | L46: =IFERROR(('Historical Financials'!L56-'Historical Financials'!K56)/'Historical Financials'!K56,"-") -> -
B47: Other WC Items | D47: =('Historical Financials'!D57-'Historical Financials'!C57)/'Historical Financials'!C57 -> 1.0186916 | E47: =('Historical Financials'!E57-'Historical Financials'!D57)/'Historical Financials'!D57 -> -0.49845679 | F47: =('Historical Financials'!F57-'Historical Financials'!E57)/'Historical Financials'!E57 -> 2.76 | G47: =('Historical Financials'!G57-'Historical Financials'!F57)/'Historical Financials'!F57 -> -0.31342062 | H47: =('Historical Financials'!H57-'Historical Financials'!G57)/'Historical Financials'!G57 -> -0.32181168 | I47: =('Historical Financials'!I57-'Historical Financials'!H57)/'Historical Financials'!H57 -> -2.516696 | J47: =('Historical Financials'!J57-'Historical Financials'!I57)/'Historical Financials'!I57 -> -1.9281576 | K47: =('Historical Financials'!K57-'Historical Financials'!J57)/'Historical Financials'!J57 -> -2.4506866 | L47: =('Historical Financials'!L57-'Historical Financials'!K57)/'Historical Financials'!K57 -> -0.76850258
B48: Working Capital Changes | D48: =('Historical Financials'!D58-'Historical Financials'!C58)/'Historical Financials'!C58 -> 0.0040431267 | E48: =('Historical Financials'!E58-'Historical Financials'!D58)/'Historical Financials'!D58 -> 0.95973154 | F48: =('Historical Financials'!F58-'Historical Financials'!E58)/'Historical Financials'!E58 -> 0.50136986 | G48: =('Historical Financials'!G58-'Historical Financials'!F58)/'Historical Financials'!F58 -> 0.2810219 | H48: =('Historical Financials'!H58-'Historical Financials'!G58)/'Historical Financials'!G58 -> -1.4683048 | I48: =('Historical Financials'!I58-'Historical Financials'!H58)/'Historical Financials'!H58 -> 0.95437262 | J48: =('Historical Financials'!J58-'Historical Financials'!I58)/'Historical Financials'!I58 -> -2.6871595 | K48: =('Historical Financials'!K58-'Historical Financials'!J58)/'Historical Financials'!J58 -> -1.6487546 | L48: =('Historical Financials'!L58-'Historical Financials'!K58)/'Historical Financials'!K58 -> -0.96551724
B49: Direct Taxes | D49: =('Historical Financials'!D59-'Historical Financials'!C59)/'Historical Financials'!C59 -> 0.25291375 | E49: =('Historical Financials'!E59-'Historical Financials'!D59)/'Historical Financials'!D59 -> 0.77860465 | F49: =('Historical Financials'!F59-'Historical Financials'!E59)/'Historical Financials'!E59 -> 0.21495816 | G49: =('Historical Financials'!G59-'Historical Financials'!F59)/'Historical Financials'!F59 -> 0.31554025 | H49: =('Historical Financials'!H59-'Historical Financials'!G59)/'Historical Financials'!G59 -> 0.028795812 | I49: =('Historical Financials'!I59-'Historical Financials'!H59)/'Historical Financials'!H59 -> -0.54262087 | J49: =('Historical Financials'!J59-'Historical Financials'!I59)/'Historical Financials'!I59 -> -0.29694019 | K49: =('Historical Financials'!K59-'Historical Financials'!J59)/'Historical Financials'!J59 -> 0.16518299 | L49: =('Historical Financials'!L59-'Historical Financials'!K59)/'Historical Financials'!K59 -> 0.92275042
...

Sheet Common Size Statement
B2: ="Common Size Statement"&" - "&'Historical Financials'!B1 -> Common Size Statement - MARUTI SUZUKI LTD
B3: Year | C3: 2016 | D3: =C3+1 -> 2017 | E3: =D3+1 -> 2018 | F3: =E3+1 -> 2019 | G3: =F3+1 -> 2020 | H3: =G3+1 -> 2021 | I3: =H3+1 -> 2022 | J3: =I3+1 -> 2023 | K3: =J3+1 -> 2024 | L3: =K3+1 -> 2025
B5: Income Statement
B6: Sales | C6: ='Historical Financials'!C7/'Historical Financials'!C$7 -> 1 | D6: ='Historical Financials'!D7/'Historical Financials'!D$7 -> 1 | E6: ='Historical Financials'!E7/'Historical Financials'!E$7 -> 1 | F6: ='Historical Financials'!F7/'Historical Financials'!F$7 -> 1 | G6: ='Historical Financials'!G7/'Historical Financials'!G$7 -> 1 | H6: ='Historical Financials'!H7/'Historical Financials'!H$7 -> 1 | I6: ='Historical Financials'!I7/'Historical Financials'!I$7 -> 1 | J6: ='Historical Financials'!J7/'Historical Financials'!J$7 -> 1 | ... L6: ='Historical Financials'!L7/'Historical Financials'!L$7 -> 1
B7: COGS | C7: ='Historical Financials'!C8/'Historical Financials'!C$7 -> 0.72632274 | D7: ='Historical Financials'!D8/'Historical Financials'!D$7 -> 0.7344349 | E7: ='Historical Financials'!E8/'Historical Financials'!E$7 -> 0.73907334 | F7: ='Historical Financials'!F8/'Historical Financials'!F$7 -> 0.74571068 | G7: ='Historical Financials'!G8/'Historical Financials'!G$7 -> 0.76205525 | H7: ='Historical Financials'!H8/'Historical Financials'!H$7 -> 0.78746661 | I7: ='Historical Financials'!I8/'Historical Financials'!I$7 -> 0.81035845 | J7: ='Historical Financials'!J8/'Historical Financials'!J$7 -> 0.78313215 | ... L7: ='Historical Financials'!L8/'Historical Financials'!L$7 -> 0.74890166
B8: Gross Profit | C8: ='Historical Financials'!C9/'Historical Financials'!C$7 -> 0.27367726 | D8: ='Historical Financials'!D9/'Historical Financials'!D$7 -> 0.2655651 | E8: ='Historical Financials'!E9/'Historical Financials'!E$7 -> 0.26092666 | F8: ='Historical Financials'!F9/'Historical Financials'!F$7 -> 0.25428932 | G8: ='Historical Financials'!G9/'Historical Financials'!G$7 -> 0.23794475 | H8: ='Historical Financials'!H9/'Historical Financials'!H$7 -> 0.21253339 | I8: ='Historical Financials'!I9/'Historical Financials'!I$7 -> 0.18964155 | J8: ='Historical Financials'!J9/'Historical Financials'!J$7 -> 0.21686785 | ... L8: ='Historical Financials'!L9/'Historical Financials'!L$7 -> 0.25109834
B9: Selling & General Expenses | C9: ='Historical Financials'!C10/'Historical Financials'!C$7 -> 0.11697894 | D9: ='Historical Financials'!D10/'Historical Financials'!D$7 -> 0.11250202 | E9: ='Historical Financials'!E10/'Historical Financials'!E$7 -> 0.10909116 | F9: ='Historical Financials'!F10/'Historical Financials'!F$7 -> 0.12583001 | G9: ='Historical Financials'!G10/'Historical Financials'!G$7 -> 0.14073354 | H9: ='Historical Financials'!H10/'Historical Financials'!H$7 -> 0.1356477 | I9: ='Historical Financials'!I10/'Historical Financials'!I$7 -> 0.12452196 | J9: ='Historical Financials'!J10/'Historical Financials'!J$7 -> 0.10605363 | ... L9: ='Historical Financials'!L10/'Historical Financials'!L$7 -> 0.11928286
B10: EBITDA | C10: ='Historical Financials'!C11/'Historical Financials'!C$7 -> 0.15669833 | D10: ='Historical Financials'!D11/'Historical Financials'!D$7 -> 0.15306308 | E10: ='Historical Financials'!E11/'Historical Financials'!E$7 -> 0.1518355 | F10: ='Historical Financials'!F11/'Historical Financials'!F$7 -> 0.12845931 | G10: ='Historical Financials'!G11/'Historical Financials'!G$7 -> 0.097211208 | H10: ='Historical Financials'!H11/'Historical Financials'!H$7 -> 0.076885693 | I10: ='Historical Financials'!I11/'Historical Financials'!I$7 -> 0.065119586 | J10: ='Historical Financials'!J11/'Historical Financials'!J$7 -> 0.11081421 | ... L10: ='Historical Financials'!L11/'Historical Financials'!L$7 -> 0.13181548
B11: Depreciation | C11: ='Historical Financials'!C12/'Historical Financials'!C$7 -> 0.048998941 | D11: ='Historical Financials'!D12/'Historical Financials'!D$7 -> 0.038244841 | E11: ='Historical Financials'!E12/'Historical Financials'!E$7 -> 0.034579887 | F11: ='Historical Financials'!F12/'Historical Financials'!F$7 -> 0.035097626 | G11: ='Historical Financials'!G12/'Historical Financials'!G$7 -> 0.046634946 | H11: ='Historical Financials'!H12/'Historical Financials'!H$7 -> 0.043115159 | I11: ='Historical Financials'!I12/'Historical Financials'!I$7 -> 0.031574848 | J11: ='Historical Financials'!J12/'Historical Financials'!J$7 -> 0.040925632 | ... L11: ='Historical Financials'!L12/'Historical Financials'!L$7 -> 0.036675757
B12: EBIT | C12: ='Historical Financials'!C13/'Historical Financials'!C$7 -> 0.10769939 | D12: ='Historical Financials'!D13/'Historical Financials'!D$7 -> 0.11481824 | E12: ='Historical Financials'!E13/'Historical Financials'!E$7 -> 0.11725561 | F12: ='Historical Financials'!F13/'Historical Financials'!F$7 -> 0.093361683 | G12: ='Historical Financials'!G13/'Historical Financials'!G$7 -> 0.050576262 | H12: ='Historical Financials'!H13/'Historical Financials'!H$7 -> 0.033770534 | I12: ='Historical Financials'!I13/'Historical Financials'!I$7 -> 0.033544738 | J12: ='Historical Financials'!J13/'Historical Financials'!J$7 -> 0.069888582 | ... L12: ='Historical Financials'!L13/'Historical Financials'!L$7 -> 0.09513972
B13: Interest | C13: ='Historical Financials'!C14/'Historical Financials'!C$7 -> 0.0014186737 | D13: ='Historical Financials'!D14/'Historical Financials'!D$7 -> 0.0013130646 | E13: ='Historical Financials'!E14/'Historical Financials'!E$7 -> 0.004332823 | F13: ='Historical Financials'!F14/'Historical Financials'!F$7 -> 0.00088185573 | G13: ='Historical Financials'!G14/'Historical Financials'!G$7 -> 0.0017737246 | H13: ='Historical Financials'!H14/'Historical Financials'!H$7 -> 0.0014465981 | I13: ='Historical Financials'!I14/'Historical Financials'!I$7 -> 0.0014332649 | J13: ='Historical Financials'!J14/'Historical Financials'!J$7 -> 0.002130734 | ... L13: ='Historical Financials'!L14/'Historical Financials'!L$7 -> 0.0012700032
B14: Other Income | C14: ='Historical Financials'!C15/'Historical Financials'!C$7 -> 0.025423258 | D14: ='Historical Financials'!D15/'Historical Financials'!D$7 -> 0.035238305 | E14: ='Historical Financials'!E15/'Historical Financials'!E$7 -> 0.02699682 | F14: ='Historical Financials'!F15/'Historical Financials'!F$7 -> 0.030954414 | G14: ='Historical Financials'!G15/'Historical Financials'!G$7 -> 0.045075337 | H14: ='Historical Financials'!H15/'Historical Financials'!H$7 -> 0.043288524 | I14: ='Historical Financials'!I15/'Historical Financials'!I$7 -> 0.021066503 | J14: ='Historical Financials'!J15/'Historical Financials'!J$7 -> 0.020395254 | ... L14: ='Historical Financials'!L15/'Historical Financials'!L$7 -> 0.034438537
B15: EBT | C15: ='Historical Financials'!C16/'Historical Financials'!C$7 -> 0.080857455 | D15: ='Historical Financials'!D16/'Historical Financials'!D$7 -> 0.078266872 | E15: ='Historical Financials'!E16/'Historical Financials'!E$7 -> 0.085925969 | F15: ='Historical Financials'!F16/'Historical Financials'!F$7 -> 0.061525413 | G15: ='Historical Financials'!G16/'Historical Financials'!G$7 -> 0.0037272006 | H15: ='Historical Financials'!H16/'Historical Financials'!H$7 -> -0.010964588 | I15: ='Historical Financials'!I16/'Historical Financials'!I$7 -> 0.01104497 | J15: ='Historical Financials'!J16/'Historical Financials'!J$7 -> 0.047362594 | ... L15: ='Historical Financials'!L16/'Historical Financials'!L$7 -> 0.05943118
B16: Tax | C16: ='Historical Financials'!C17/'Historical Financials'!C$7 -> 0.036248242 | D16: ='Historical Financials'!D17/'Historical Financials'!D$7 -> 0.038425498 | E16: ='Historical Financials'!E17/'Historical Financials'!E$7 -> 0.041175601 | F16: ='Historical Financials'!F17/'Historical Financials'!F$7 -> 0.034544578 | G16: ='Historical Financials'!G17/'Historical Financials'!G$7 -> 0.018836902 | H16: ='Historical Financials'!H17/'Historical Financials'!H$7 -> 0.013242483 | I16: ='Historical Financials'!I17/'Historical Financials'!I$7 -> 0.0092573514 | J16: ='Historical Financials'!J17/'Historical Financials'!J$7 -> 0.018364174 | ... L16: ='Historical Financials'!L17/'Historical Financials'!L$7 -> 0.033481784
B17: Net Profit | C17: ='Historical Financials'!C18/'Historical Financials'!C$7 -> 0.044609214 | D17: ='Historical Financials'!D18/'Historical Financials'!D$7 -> 0.039841375 | E17: ='Historical Financials'!E18/'Historical Financials'!E$7 -> 0.044750368 | F17: ='Historical Financials'!F18/'Historical Financials'!F$7 -> 0.026980835 | G17: ='Historical Financials'!G18/'Historical Financials'!G$7 -> -0.015109701 | H17: ='Historical Financials'!H18/'Historical Financials'!H$7 -> -0.024207071 | I17: ='Historical Financials'!I18/'Historical Financials'!I$7 -> 0.0017876187 | J17: ='Historical Financials'!J18/'Historical Financials'!J$7 -> 0.02899842 | ... L17: ='Historical Financials'!L18/'Historical Financials'!L$7 -> 0.025949396
B19: Balance Sheet
B20: Total Liabilities | C20: =IFERROR('Historical Financials'!C34/'Historical Financials'!C$47,"-") -> 0.90458416 | D20: =IFERROR('Historical Financials'!D34/'Historical Financials'!D$47,"-") -> 0.92046455 | E20: =IFERROR('Historical Financials'!E34/'Historical Financials'!E$47,"-") -> 0.92764057 | F20: =IFERROR('Historical Financials'!F34/'Historical Financials'!F$47,"-") -> 0.91656338 | G20: =IFERROR('Historical Financials'!G34/'Historical Financials'!G$47,"-") -> 0.92417242 | H20: =IFERROR('Historical Financials'!H34/'Historical Financials'!H$47,"-") -> 0.90633901 | I20: =IFERROR('Historical Financials'!I34/'Historical Financials'!I$47,"-") -> 0.8966066 | J20: =IFERROR('Historical Financials'!J34/'Historical Financials'!J$47,"-") -> 0.89714544 | ... L20: =IFERROR('Historical Financials'!L34/'Historical Financials'!L$47,"-") -> 0.90405514
B21: Equity Share Capital | C21: ='Historical Financials'!C30/'Historical Financials'!C$47 -> 0.0031969716 | D21: ='Historical Financials'!D30/'Historical Financials'!D$47 -> 0.0026749194 | E21: ='Historical Financials'!E30/'Historical Financials'!E$47 -> 0.0023249369 | F21: ='Historical Financials'!F30/'Historical Financials'!F$47 -> 0.0021635749 | G21: ='Historical Financials'!G30/'Historical Financials'!G$47 -> 0.0021932277 | H21: ='Historical Financials'!H30/'Historical Financials'!H$47 -> 0.0019174092 | I21: ='Historical Financials'!I30/'Historical Financials'!I$47 -> 0.0018134979 | J21: ='Historical Financials'!J30/'Historical Financials'!J$47 -> 0.0014088193 | ... L21: ='Historical Financials'!L30/'Historical Financials'!L$47 -> 0.0010768775
B22: Reserves | C22: ='Historical Financials'!C31/'Historical Financials'!C$47 -> 0.64500489 | D22: ='Historical Financials'!D31/'Historical Financials'!D$47 -> 0.65409927 | E22: ='Historical Financials'!E31/'Historical Financials'!E$47 -> 0.65295929 | F22: ='Historical Financials'!F31/'Historical Financials'!F$47 -> 0.67258665 | G22: ='Historical Financials'!G31/'Historical Financials'!G$47 -> 0.71551513 | H22: ='Historical Financials'!H31/'Historical Financials'!H$47 -> 0.6647391 | I22: ='Historical Financials'!I31/'Historical Financials'!I$47 -> 0.66273742 | J22: ='Historical Financials'!J31/'Historical Financials'!J$47 -> 0.66715479 | ... L22: ='Historical Financials'!L31/'Historical Financials'!L$47 -> 0.65820167
B23: Borrowings | C23: ='Historical Financials'!C32/'Historical Financials'!C$47 -> 0.0048886141 | D23: ='Historical Financials'!D32/'Historical Financials'!D$47 -> 0.0085668278 | E23: ='Historical Financials'!E32/'Historical Financials'!E$47 -> 0.0018599495 | F23: ='Historical Financials'!F32/'Historical Financials'!F$47 -> 0.0022867983 | G23: ='Historical Financials'!G32/'Historical Financials'!G$47 -> 0.0026739949 | H23: ='Historical Financials'!H32/'Historical Financials'!H$47 -> 0.0068683883 | I23: ='Historical Financials'!I32/'Historical Financials'!I$47 -> 0.005110221 | J23: ='Historical Financials'!J32/'Historical Financials'!J$47 -> 0.011180935 | ... L23: ='Historical Financials'!L32/'Historical Financials'!L$47 -> 0.00059598185
